Workbook

Sheet Overview
A1: PORTFOLIO A — QUALITY GROWTH
A5: STRATEGY
A6: • Own profitable businesses with room to reinvest and expand.
A7: • Emphasize technology, healthcare innovation and industrial investment.
A8: • Main risks: valuation, AI spending and economic growth sensitivity.
A10: PORTFOLIO SNAPSHOT
A12: HOLDINGS | C12: TOTAL WEIGHT | D12: AVG MARKET CAP | F12: WEIGHTED BETA | G12: BELOW $5BN
A13: =COUNTA(Holdings!#REF!) -> 1 | C13: =SUM(Holdings!G3:G52) -> 1 | D13: =AVERAGE(Holdings!F3:F52) -> 614.9502 | F13: =SUMPRODUCT(Holdings!G3:G52,Holdings!N3:N52) -> 0.9558 | G13: =COUNTIF(Holdings!O3:O52,"Yes") -> 5
A14: names | C14: of portfolio | D14: arithmetic mean | F14: Finviz vendor est. | G14: small-cap names
A16: SECTOR ALLOCATION
A17: Sector | D17: Holdings | E17: Weight | G17: Weight vs. Portfolio
A18: Communication Services | D18: =COUNTIF(Holdings!$C$3:$C$52,A18) -> 3 | E18: =SUMIF(Holdings!$C$3:$C$52,A18,Holdings!$G$3:$G$52) -> 0.06 | G18: =E18 -> 0.06
A19: Consumer Discretionary | D19: =COUNTIF(Holdings!$C$3:$C$52,A19) -> 4 | E19: =SUMIF(Holdings!$C$3:$C$52,A19,Holdings!$G$3:$G$52) -> 0.08 | G19: =E19 -> 0.08
A20: Consumer Staples | D20: =COUNTIF(Holdings!$C$3:$C$52,A20) -> 4 | E20: =SUMIF(Holdings!$C$3:$C$52,A20,Holdings!$G$3:$G$52) -> 0.08 | G20: =E20 -> 0.08
A21: Energy | D21: =COUNTIF(Holdings!$C$3:$C$52,A21) -> 4 | E21: =SUMIF(Holdings!$C$3:$C$52,A21,Holdings!$G$3:$G$52) -> 0.08 | G21: =E21 -> 0.08
A22: Financials | D22: =COUNTIF(Holdings!$C$3:$C$52,A22) -> 3 | E22: =SUMIF(Holdings!$C$3:$C$52,A22,Holdings!$G$3:$G$52) -> 0.06 | G22: =E22 -> 0.06
A23: Health Care | D23: =COUNTIF(Holdings!$C$3:$C$52,A23) -> 9 | E23: =SUMIF(Holdings!$C$3:$C$52,A23,Holdings!$G$3:$G$52) -> 0.18 | G23: =E23 -> 0.18
A24: Industrials | D24: =COUNTIF(Holdings!$C$3:$C$52,A24) -> 7 | E24: =SUMIF(Holdings!$C$3:$C$52,A24,Holdings!$G$3:$G$52) -> 0.14 | G24: =E24 -> 0.14
A25: Information Technology | D25: =COUNTIF(Holdings!$C$3:$C$52,A25) -> 12 | E25: =SUMIF(Holdings!$C$3:$C$52,A25,Holdings!$G$3:$G$52) -> 0.24 | G25: =E25 -> 0.24
A26: Materials | D26: =COUNTIF(Holdings!$C$3:$C$52,A26) -> 2 | E26: =SUMIF(Holdings!$C$3:$C$52,A26,Holdings!$G$3:$G$52) -> 0.04 | G26: =E26 -> 0.04
A27: Real Estate | D27: =COUNTIF(Holdings!$C$3:$C$52,A27) -> 1 | E27: =SUMIF(Holdings!$C$3:$C$52,A27,Holdings!$G$3:$G$52) -> 0.02 | G27: =E27 -> 0.02
A28: Utilities | D28: =COUNTIF(Holdings!$C$3:$C$52,A28) -> 1 | E28: =SUMIF(Holdings!$C$3:$C$52,A28,Holdings!$G$3:$G$52) -> 0.02 | G28: =E28 -> 0.02
A29: Total | D29: =SUM(D18:D28) -> 50 | E29: =SUM(E18:E28) -> 1
A48: NOTES & METHODOLOGY
A49: — Basis: September 10, 2026 snapshots; equal weights of 2% are proposed.
A50: — Average market cap is an arithmetic mean, not a portfolio valuation.
A51: — Beta is a weighted average of vendor estimates, not measured portfolio volatility.
A52: — Historical coverage, fiscal year ends and company notes are carried from the group workbook.
A53: — Fields not verified in the group workbook remain blank or retain their original qualification.
A54: — Finviz figures use the snapshots underlying our two-portfolio comparison; they are not live.
A55: — Both portfolios use the same shared universe of 116 names; selections reflect business fit.

Sheet Holdings
C1: Company | F1: Position | H1: Fundamentals & Momentum | O1: Size Flag | P1: Investment Thesis | R1: Coverage Notes | U1: Source
B2: Ticker | C2: Sector | D2: Industry | E2: Company Name | F2: Market Cap ($bn) | G2: Proposed Weight | H2: Trailing P/E | I2: ROIC (%) | J2: 3Y Rev. CAGR (%) | K2: Debt/Equity | L2: 6M Price Return (%) | M2: Price vs. 200D MA (%) | N2: Finviz Beta | O2: Below $5bn? | P2: Selection Rationale | Q2: Key Risk | R2: Data Avail. from Dec 2009? | S2: Delisted/Failed/Acquired? | T2: Financial Year End | U2: Data As Of | V2: Source URL | W2: Contributor(s)
A3: 1 | B3: AAPL | C3: Information Technology | E3: Apple Inc. | F3: 4712.39 | G3: 0.02 | H3: 37.02 | I3: 0.7208 | J3: 0.0181 | K3: 0.78 | L3: 0.238 | M3: 0.1344 | N3: 1.08 | O3: No | P3: Large-cap tech; long history | Q3: iPhone concentration / valuation | S3: No | T3: Sep | U3: 46275 | V3: https://finviz.com/stock?t=AAPL | W3: Evan, Skye
A4: 2 | B4: ABT | C4: Health Care | E4: Abbott Laboratories | F4: 180.77 | G4: 0.02 | H4: 33.77 | I4: 0.067 | J4: 0.0051 | K4: 0.64 | L4: -0.0524 | M4: -0.0143 | N4: 0.58 | O4: No | P4: Diversified health care exposure | Q4: Regulatory / product risk | S4: No | T4: Dec | U4: 46275 | V4: https://finviz.com/stock?t=ABT | W4: Evan, Skye
A5: 3 | B5: ADBE | C5: Information Technology | D5: Application Software | E5: Adobe Inc | F5: 100.37 | G5: 0.02 | H5: 14.44 | I5: 0.4342 | J5: 0.1089 | K5: 0.61 | L5: -0.0774 | M5: -0.0542 | N5: 1.41 | O5: No | P5: Recurring creative-software revenue; strong profitability and cash generation | Q5: AI competition; negative price momentum | R5: Yes—monthly prices | S5: Active listed | T5: November | U5: 46275 | V5: https://finviz.com/stock?t=ADBE | W5: Ashley
A6: 4 | B6: ADUS | C6: Health Care | D6: Medical Care Facilities | E6: Addus HomeCare Corp | F6: 2.21 | G6: 0.02 | H6: 20.77 | I6: 0.0847 | J6: 0.1436 | K6: 0.09 | L6: 0.1492 | M6: 0.1197 | N6: 0.82 | O6: Yes | P6: Growing home-care revenue and low leverage | Q6: Reimbursement rates; labor availability; smaller-company liquidity | R6: Yes—monthly prices | S6: Active listed | T6: December | U6: 46275 | V6: https://finviz.com/stock?t=ADUS | W6: Ashley
A7: 5 | B7: AMGN | C7: Health Care | D7: Drug Manufacturers - General | E7: AMGEN Inc | F7: 207.71 | G7: 0.02 | H7: 23.87 | I7: 0.1376 | J7: 0.1209 | K7: 4.9 | L7: 0.0173 | M7: 0.0696 | N7: 0.42 | O7: No | P7: Established medicines and positive cash generation | Q7: High leverage; patent and pipeline risks | R7: Yes—monthly prices | S7: Active listed | T7: December | U7: 46275 | V7: https://finviz.com/stock?t=AMGN | W7: Ashley, Evan
A8: 6 | B8: AMZN | C8: Consumer Discretionary | E8: Amazon.com, Inc. | F8: 2720.36 | G8: 0.02 | H8: 20.29 | I8: 0.1746 | J8: 0.1173 | K8: 0.44 | L8: 0.186 | M8: 0.0525 | N8: 1.45 | O8: No | P8: E-commerce/cloud exposure | Q8: Valuation / competition | S8: No | T8: Dec | U8: 46275 | V8: https://finviz.com/stock?t=AMZN | W8: Evan
A9: 7 | B9: CAT | C9: Industrials | E9: Caterpillar Inc. | F9: 370.86 | G9: 0.02 | H9: 34.7 | I9: 0.2108 | J9: 0.0438 | K9: 2.33 | L9: 0.1402 | M9: 0.0381 | N9: 1.58 | O9: No | P9: Industrial/cyclical exposure | Q9: Economic-cycle risk | S9: No | T9: Dec | U9: 46275 | V9: https://finviz.com/stock?t=CAT | W9: Evan, Skye
A10: 8 | B10: CMCSA | C10: Communication Services | D10: Telecom Services | E10: Comcast Corp | F10: 89.04 | G10: 0.02 | H10: 8.12 | I10: 0.0644 | J10: 0.0062 | K10: 1.01 | L10: -0.1793 | M10: -0.0678 | N10: 0.66 | O10: No | P10: Low earnings and cash-flow multiples | Q10: Broadband competition; structural media changes; weak momentum | R10: Yes—monthly prices | S10: Active listed; spin-off history | T10: December | U10: 46275 | V10: https://finviz.com/stock?t=CMCSA | W10: Ashley, Evan, Skye
A11: 9 | B11: COST | C11: Consumer Staples | E11: Costco Wholesale | F11: 400.35 | G11: 0.02 | H11: 45.41 | I11: 0.2122 | J11: 0.0664 | K11: 0.25 | L11: -0.0902 | M11: -0.0601 | N11: 0.88 | O11: No | P11: Defensive retail exposure | Q11: High valuation | S11: No | T11: Aug | U11: 46275 | V11: https://finviz.com/stock?t=COST | W11: Evan
A12: 10 | B12: CSCO | C12: Information Technology | E12: Cisco Systems | F12: 429.66 | G12: 0.02 | H12: 32.74 | I12: 0.1871 | J12: 0.0357 | K12: 0.62 | L12: 0.3954 | M12: 0.1443 | N12: 0.98 | O12: No | P12: Networking technology exposure | Q12: Slow growth / competition | S12: No | T12: Jul | U12: 46275 | V12: https://finviz.com/stock?t=CSCO | W12: Evan, Skye
A13: 11 | B13: CVX | C13: Energy | D13: Oil & Gas Integrated | E13: Chevron Corp | F13: 419.54 | G13: 0.02 | H13: 20.36 | I13: 0.0909 | J13: -0.0792 | K13: 0.2 | L13: 0.1071 | M13: 0.1666 | N13: 0.52 | O13: No | P13: Integrated energy operations with low reported leverage | Q13: Oil prices; project execution | R13: Yes—monthly prices | S13: Active listed | T13: December | U13: 46275 | V13: https://finviz.com/stock?t=CVX | W13: Ashley, Evan, Skye
A14: 12 | B14: DIS | C14: Communication Services | E14: Walt Disney Co. | F14: 180.22 | G14: 0.02 | H14: 21.53 | I14: 0.0583 | J14: 0.0448 | K14: 0.42 | L14: 0.0345 | M14: 0.004 | N14: 1.42 | O14: No | P14: Media/entertainment exposure | Q14: Streaming profitability | S14: No | T14: Sep | U14: 46275 | V14: https://finviz.com/stock?t=DIS | W14: Evan, Skye
A15: 13 | B15: ECL | C15: Materials | D15: Specialty Chemicals | E15: Ecolab Inc. | F15: 75.47 | G15: 0.02 | H15: 36.11 | I15: 0.0939 | J15: 0.0426 | K15: 1.38 | L15: -0.0281 | M15: -0.0141 | N15: 0.88 | O15: No | P15: Specialty-chemicals name adds a quality materials exposure. | Q15: Input costs and valuation. | R15: Provisional Yes* (Finviz IPO: 1980-03-17) | S15: No — active Finviz listing | T15: N/A — not a Finviz screener field | U15: 46275 | V15: https://finviz.com/stock?t=ECL | W15: Emily
A16: 14 | B16: EMR | C16: Industrials | E16: Emerson Electric | F16: 82.89 | G16: 0.02 | H16: 32.47 | I16: 0.0906 | J16: 0.0927 | K16: 0.68 | L16: 0.0647 | M16: 0.0387 | N16: 1.21 | O16: No | P16: Industrial automation exposure | Q16: Industrial cycle | S16: No | T16: Sep | U16: 46275 | V16: https://finviz.com/stock?t=EMR | W16: Evan
A17: 15 | B17: EOG | C17: Energy | D17: Oil & Gas Exploration & Production | E17: EOG Resources Inc | F17: 75.86 | G17: 0.02 | H17: 11.25 | I17: 0.1729 | J17: -0.0854 | K17: 0.26 | L17: 0.0914 | M17: 0.1189 | N17: 0.35 | O17: No | P17: High reported capital returns with relatively low leverage | Q17: Oil-price exposure; declining three-year reported revenue | R17: Yes—monthly prices | S17: Active listed | T17: December | U17: 46275 | V17: https://finviz.com/stock?t=EOG | W17: Ashley
A18: 16 | B18: EXEL | C18: Health Care | D18: Biotechnology | E18: Exelixis Inc | F18: 14.35 | G18: 0.02 | H18: 18.19 | I18: 0.4282 | J18: 0.1293 | K18: 0.09 | L18: 0.3871 | M18: 0.2093 | N18: 0.47 | O18: No | P18: High reported capital returns and low leverage | Q18: Dependence on key oncology products | R18: Yes—monthly prices | S18: Active listed | T18: December | U18: 46275 | V18: https://finviz.com/stock?t=EXEL | W18: Ashley
A19: 17 | B19: FFIV | C19: Information Technology | D19: Infrastructure Software | E19: F5 Inc | F19: 22.75 | G19: 0.02 | H19: 32.01 | I19: 0.1783 | J19: 0.0463 | K19: 0.07 | L19: 0.3878 | M19: 0.2183 | N19: 1.04 | O19: No | P19: Low leverage and profitable application-delivery infrastructure | Q19: Modest growth; competition | R19: Yes—monthly prices | S19: Active listed | T19: September | U19: 46275 | V19: https://finviz.com/stock?t=FFIV | W19: Ashley
A20: 18 | B20: GD | C20: Industrials | D20: Aerospace & Defense | E20: General Dynamics Corp | F20: 95.9 | G20: 0.02 | H20: 21.61 | I20: 0.1292 | J20: 0.1007 | K20: 0.35 | L20: 0.0017 | M20: -0.0008 | N20: 0.32 | O20: No | P20: Low leverage and cash-generating defense operations | Q20: Government procurement; aircraft demand; borderline price trend | R20: Yes—monthly prices | S20: Active listed | T20: December | U20: 46275 | V20: https://finviz.com/stock?t=GD | W20: Ashley
A21: 19 | B21: GE | C21: Industrials | D21: Industrial Conglomerates | E21: GE Aerospace (General Electric) | F21: 337.29 | G21: 0.02 | H21: 38.32 | I21: 0.2518 | J21: -0.0759 | K21: 1.15 | L21: -0.0002 | M21: 0.0101 | N21: 1.38 | O21: No | P21: Legacy industrial conglomerate, long history through multiple spin-offs | Q21: Aerospace cycle; historical conglomerate discount legacy | R21: Yes | S21: No | T21: December | U21: 46275 | V21: https://finviz.com/stock?t=GE | W21: Skye
A22: 20 | B22: GOOGL | C22: Communication Services | D22: Internet Content & Information | E22: Alphabet Inc. | F22: 4042.28 | G22: 0.02 | H22: 16.66 | I22: 0.3233 | J22: 0.1278 | K22: 0.18 | L22: 0.074 | M22: -0.015 | N22: 1.22 | O22: No | P22: Large digital-advertising/cloud platform; strong communications exposure. | Q22: Regulation, AI competition and advertising cyclicality. | R22: Provisional Yes* (Finviz IPO: 2004-08-19) | S22: No — active Finviz listing | T22: N/A — not a Finviz screener field | U22: 46275 | V22: https://finviz.com/stock?t=GOOGL | W22: Emily
A23: 21 | B23: GS | C23: Financials | D23: Capital Markets | E23: Goldman Sachs Group Inc. | F23: 298.39 | G23: 0.02 | H23: 15.82 | I23: 0.0433 | J23: 0.2334 | K23: 6.5 | L23: 0.244 | M23: 0.0766 | N23: 1.27 | O23: No | P23: Capital-markets exposure complements commercial banks. | Q23: Trading/investment-banking cycle and leverage. | R23: Provisional Yes* (Finviz IPO: 1999-05-04) | S23: No — active Finviz listing | T23: N/A — not a Finviz screener field | U23: 46275 | V23: https://finviz.com/stock?t=GS | W23: Emily, Skye
A24: 22 | B24: HD | C24: Consumer Discretionary | D24: Home Improvement Retail | E24: Home Depot Inc | F24: 306.95 | G24: 0.02 | H24: 21.53 | I24: 0.207 | J24: 0.0152 | K24: 3.77 | L24: -0.1231 | M24: -0.1045 | N24: 0.99 | O24: No | P24: Profitable home-improvement franchise with cash generation | Q24: Housing demand; leverage; weak momentum | R24: Yes—monthly prices | S24: Active listed | T24: January/February (52/53 weeks) | U24: 46275 | V24: https://finviz.com/stock?t=HD | W24: Ashley, Emily, Evan, Skye
A25: 23 | B25: INCY | C25: Health Care | D25: Biotechnology | E25: Incyte Corp | F25: 25.4 | G25: 0.02 | H25: 15.97 | I25: 0.253 | J25: 0.1484 | K25: 0.01 | L25: 0.3238 | M25: 0.1927 | N25: 0.73 | O25: No | P25: Profitable drug portfolio, revenue growth and very low debt | Q25: Product concentration and patent exposure | R25: Yes—monthly prices | S25: Active listed | T25: December | U25: 46275 | V25: https://finviz.com/stock?t=INCY | W25: Ashley
A26: 24 | B26: JNJ | C26: Health Care | D26: Drug Manufacturers - General | E26: Johnson & Johnson | F26: 641.86 | G26: 0.02 | H26: 30.87 | I26: 0.172 | J26: 0.0556 | K26: 0.58 | L26: 0.0961 | M26: 0.1247 | N26: 0.2 | O26: No | P26: Diversified health-care exposure with very long history. | Q26: Litigation, regulation and product/pipeline risk. | R26: Provisional Yes* (Finviz IPO: 1944-09-25) | S26: No — active Finviz listing | T26: N/A — not a Finviz screener field | U26: 46275 | V26: https://finviz.com/stock?t=JNJ | W26: Emily, Evan, Skye
A27: 25 | B27: JPM | C27: Financials | D27: Banks - Diversified | E27: JPMorgan Chase & Co | F27: 936.29 | G27: 0.02 | H27: 15.09 | I27: 0.0741 | J27: 0.21 | K27: 3.41 | L27: 0.2251 | M27: 0.1037 | N27: 1.01 | O27: No | P27: High reported bank profitability and diversified revenue sources | Q27: Premium book valuation; credit and market risks | R27: Yes—monthly prices | S27: Active listed | T27: December | U27: 46275 | V27: https://finviz.com/stock?t=JPM | W27: Ashley, Emily, Evan, Skye
A28: 26 | B28: KO | C28: Consumer Staples | D28: Beverages - Non-Alcoholic | E28: Coca-Cola Co. | F28: 379.95 | G28: 0.02 | H28: 26.61 | I28: 0.1957 | J28: 0.0414 | K28: 1.2 | L28: 0.1376 | M28: 0.1221 | N28: 0.32 | O28: No | P28: Defensive global beverage franchise. | Q28: FX, input costs and demand elasticity. | R28: Provisional Yes* (Finviz IPO: 1950-01-26) | S28: No — active Finviz listing | T28: N/A — not a Finviz screener field | U28: 46275 | V28: https://finviz.com/stock?t=KO | W28: Emily, Evan, Skye
A29: 27 | B29: LNN | C29: Industrials | D29: Farm & Heavy Construction Machinery | E29: Lindsay Corp. | F29: 1.22 | G29: 0.02 | H29: 22.94 | I29: 0.0872 | J29: -0.0426 | K29: 0.28 | L29: -0.0457 | M29: 0.0112 | N29: 0.67 | O29: Yes | P29: Sub-$5bn industrial adds size diversity outside Energy. | Q29: Agricultural cycle and small-cap liquidity. | R29: Provisional Yes* (Finviz IPO: 1988-10-12) | S29: No — active Finviz listing | T29: N/A — not a Finviz screener field | U29: 46275 | V29: https://finviz.com/stock?t=LNN | W29: Emily
A30: 28 | B30: MCD | C30: Consumer Discretionary | D30: Restaurants | E30: McDonald's Corp. | F30: 179.21 | G30: 0.02 | H30: 20.57 | I30: 0.1662 | J30: 0.0506 | L30: -0.2213 | M30: -0.1421 | N30: 0.44 | O30: No | P30: Global restaurant franchise with defensive/discretionary characteristics. | Q30: Consumer spending, FX; D/E not meaningful with negative equity. | R30: Provisional Yes* (Finviz IPO: 1966-07-05) | S30: No — active Finviz listing | T30: N/A — not a Finviz screener field | U30: 46275 | V30: https://finviz.com/stock?t=MCD | W30: Emily, Evan, Skye
A31: 29 | B31: MDT | C31: Health Care | D31: Medical Devices | E31: Medtronic Plc | F31: 117.63 | G31: 0.02 | H31: 22.64 | I31: 0.069 | J31: 0.0521 | K31: 0.56 | L31: 0.0336 | M31: 0.0263 | N31: 0.56 | O31: No | P31: Diversified medical-device operations with positive cash generation | Q31: Product execution; pricing pressure | R31: Yes—monthly prices | S31: Active listed; merger/reorganization history | T31: April | U31: 46275 | V31: https://finviz.com/stock?t=MDT | W31: Ashley, Evan
A32: 30 | B32: MS | C32: Financials | D32: Capital Markets | E32: Morgan Stanley | F32: 336.96 | G32: 0.02 | H32: 17.34 | I32: 0.0397 | J32: 0.2196 | K32: 4.69 | L32: 0.3335 | M32: 0.1189 | N32: 1.2 | O32: No | P32: Wealth management and investment-banking exposure. | Q32: Market cycle, trading and asset-price sensitivity. | R32: Provisional Yes* (Finviz IPO: 1986-03-21) | S32: No — active Finviz listing | T32: N/A — not a Finviz screener field | U32: 46275 | V32: https://finviz.com/stock?t=MS | W32: Emily
A33: 31 | B33: MSFT | C33: Information Technology | D33: Software - Infrastructure | E33: Microsoft Corp. | F33: 3649.4 | G33: 0.02 | H33: 27.39 | I33: 0.2422 | J33: 0.1612 | K33: 0.29 | L33: 0.2139 | M33: 0.1399 | N33: 1.1 | O33: No | P33: Mega-cap software/cloud exposure. | Q33: Valuation, regulation and AI/data-center capex. | R33: Provisional Yes* (Finviz IPO: 1986-03-13) | S33: No — active Finviz listing | T33: N/A — not a Finviz screener field | U33: 46275 | V33: https://finviz.com/stock?t=MSFT | W33: Emily, Evan, Skye
A34: 32 | B34: MU | C34: Information Technology | D34: Semiconductors | E34: Micron Technology Inc | F34: 1117.77 | G34: 0.02 | H34: 22.41 | I34: 0.4738 | J34: 0.0671 | K34: 0.06 | L34: 1.3638 | M34: 0.6007 | N34: 2.23 | O34: No | P34: High reported capital returns and low leverage | Q34: Memory-price cyclicality; extended rally | R34: Yes—monthly prices | S34: Active listed | T34: August | U34: 46275 | V34: https://finviz.com/stock?t=MU | W34: Ashley
A35: 33 | B35: NEE | C35: Utilities | D35: Utilities - Regulated Electric | E35: NextEra Energy Inc. | F35: 172.53 | G35: 0.02 | H35: 18.56 | I35: 0.0596 | J35: -0.0009 | K35: 1.93 | L35: -0.0976 | M35: -0.0579 | N35: 0.63 | O35: No | P35: Utility plus renewables exposure within a defensive sector. | Q35: Rates, financing and project execution. | R35: Provisional Yes* (Finviz IPO: 1950-02-15) | S35: No — active Finviz listing | T35: N/A — not a Finviz screener field | U35: 46275 | V35: https://finviz.com/stock?t=NEE | W35: Emily, Evan
A36: 34 | B36: NTAP | C36: Information Technology | D36: Computer Hardware and Storage | E36: Netapp Inc | F36: 36.27 | G36: 0.02 | H36: 26.06 | I36: 0.413 | J36: 0.0288 | K36: 1.69 | L36: 0.8923 | M36: 0.4007 | N36: 1.47 | O36: No | P36: Profitable enterprise storage business with cash generation | Q36: Leverage; elevated share price; small equity base | R36: Yes—monthly prices | S36: Active listed | T36: April | U36: 46275 | V36: https://finviz.com/stock?t=NTAP | W36: Ashley
A37: 35 | B37: NVDA | C37: Information Technology | D37: Semiconductors | E37: NVIDIA Corp | F37: 5253.08 | G37: 0.02 | H37: 27.55 | I37: 0.7242 | J37: 1.0005 | K37: 0.17 | L37: 0.1717 | M37: 0.1049 | N37: 2.22 | O37: No | P37: High profitability and rapid historical revenue growth | Q37: AI investment cycle; customer concentration; high beta | R37: Yes—monthly prices | S37: Active listed | T37: January | U37: 46275 | V37: https://finviz.com/stock?t=NVDA | W37: Ashley
A38: 36 | B38: OII | C38: Energy | D38: Oil & Gas Equipment & Services | E38: Oceaneering International Inc | F38: 4.98 | G38: 0.02 | H38: 14.4 | I38: 0.187 | J38: 0.1045 | K38: 0.71 | L38: 0.4146 | M38: 0.3542 | N38: 1.24 | O38: Yes | P38: Profitable subsea-services exposure and historical revenue growth | Q38: Offshore spending cycle; market cap close to the $5bn cutoff | R38: Yes—monthly prices | S38: Active listed | T38: December | U38: 46275 | V38: https://finviz.com/stock?t=OII | W38: Ashley
A39: 37 | B39: OKE | C39: Energy | D39: Oil & Gas Midstream | E39: Oneok Inc | F39: 60.03 | G39: 0.02 | H39: 16.45 | I39: 0.0681 | J39: 0.1365 | K39: 1.44 | L39: 0.1104 | M39: 0.116 | N39: 0.78 | O39: No | P39: Adds energy transportation and processing exposure | Q39: Leverage; interest rates; acquisition integration | R39: Yes—monthly prices | S39: Active listed | T39: December | U39: 46275 | V39: https://finviz.com/stock?t=OKE | W39: Ashley
A40: 38 | B40: PG | C40: Consumer Staples | D40: Household & Personal Products | E40: Procter & Gamble Co | F40: 330.86 | G40: 0.02 | H40: 21.52 | I40: 0.2069 | J40: 0.02 | K40: 0.65 | L40: -0.0709 | M40: -0.0343 | N40: 0.38 | O40: No | P40: Recurring household-product demand and profitability | Q40: Modest growth; pricing pressure; weak momentum | R40: Yes—monthly prices | S40: Active listed | T40: June | U40: 46275 | V40: https://finviz.com/stock?t=PG | W40: Ashley, Emily, Skye
...

Sheet Prices
A1: Prices
A2: Date | B2: AAPL | C2: ABT | D2: ADBE | E2: ADUS | F2: AMGN | G2: AMZN | H2: CAT | I2: CMCSA | J2: COST | K2: CSCO | L2: CVX | M2: DIS | N2: ECL | O2: EMR | P2: EOG | Q2: EXEL | R2: FFIV | S2: GD | T2: GE | U2: GOOGL | V2: GS | W2: HD | X2: INCY | Y2: JNJ | Z2: JPM | AA2: KO | AB2: LNN | AC2: MCD | AD2: MDT | AE2: MS | AF2: MSFT | AG2: MU | AH2: NEE | AI2: NTAP | AJ2: NVDA | AK2: OII | AL2: OKE | AM2: PG | AN2: PH | AO2: PLAB | AP2: PLD | AQ2: PLUS | AR2: QCOM | AS2: REGN | AT2: SHW | AU2: TJX | AV2: TXN | AW2: UNH | AX2: UNP | AY2: WMT | AZ2: ^GSPC
A3: 40179 | B3: 5.7444444 | C3: 17.702564 | D3: 32.299999 | E3: 8.8199997 | F3: 39.030663 | G3: 6.2705002 | H3: 35.080997 | I3: 5.0757422 | J3: 40.577644 | K3: 14.406988 | L3: 36.978725 | M3: 24.955511 | N3: 36.384682 | O3: 26.534134 | P3: 31.361103 | Q3: 6.6300001 | R3: 49.43 | S3: 45.725605 | T3: 55.637985 | U3: 13.136755 | V3: 110.635 | W3: 18.714933 | X3: 10.68 | Y3: 38.659321 | Z3: 25.583509 | AA3: 16.363695 | AB3: 33.526699 | AC3: 39.556202 | AD3: 28.621866 | AE3: 18.668802 | AF3: 20.927166 | AG3: 8.5031958 | AH3: 7.4803228 | AI3: 21.319498 | AJ3: 0.35232237 | AK3: 24.176914 | AL3: 7.7185235 | AM3: 38.116673 | AN3: 42.391159 | AO3: 3.8499999 | AP3: 14.3621 | AQ3: 3.6410172 | AR3: 25.784401 | AS3: 26.41077 | AT3: 17.596043 | AU3: 7.6224251 | AV3: 14.652967 | AW3: 25.40056 | AX3: 21.121809 | AY3: 12.68838 | AZ3: 1073.87
A4: 40210 | B4: 6.1201081 | C4: 18.15065 | D4: 34.650002 | E4: 7.9000001 | F4: 37.782589 | G4: 5.9200001 | H4: 38.311062 | I4: 5.2713342 | J4: 43.211235 | K4: 15.599553 | L4: 37.425835 | M4: 26.38275 | N4: 34.925972 | O4: 30.461697 | P4: 32.620132 | Q4: 6.4699998 | R4: 55.799999 | S4: 49.624424 | T4: 55.915646 | U4: 13.058919 | V4: 116.57188 | W4: 20.846338 | X4: 10.66 | Y4: 39.041866 | Z4: 27.574223 | AA4: 15.902186 | AB4: 30.733324 | AC4: 40.799786 | AD4: 28.962198 | AE4: 19.64476 | AF4: 21.39061 | AG4: 8.8347416 | AH4: 7.1904955 | AI4: 21.963545 | AJ4: 0.37086567 | AK4: 26.718365 | AL4: 8.1100311 | AM4: 39.188038 | AN4: 45.932018 | AO4: 4.4000001 | AP4: 14.565557 | AQ4: 3.7985163 | AR4: 24.239904 | AS4: 24.231333 | AT4: 17.703753 | AU4: 8.3749666 | AV4: 15.877305 | AW4: 26.062513 | AX4: 23.616316 | AY4: 12.840362 | AZ4: 1104.49
A5: 40238 | B5: 7.0287642 | C5: 17.615627 | D5: 35.369999 | E5: 6.04 | F5: 39.938347 | G5: 6.7884998 | H5: 42.205967 | I5: 6.0376658 | J5: 42.318245 | K5: 16.689547 | L5: 39.253117 | M5: 29.482126 | N5: 36.558891 | O5: 32.39212 | P5: 32.23513 | Q5: 6.0700002 | R5: 61.630001 | S5: 52.805061 | T5: 63.366463 | U5: 14.058416 | V5: 127.21877 | W5: 21.775499 | X5: 13.93 | Y5: 40.405235 | Z5: 29.400663 | AA5: 16.725693 | AB5: 34.573948 | AC5: 42.633686 | AD5: 30.049963 | AE5: 20.418568 | AF5: 21.853197 | AG5: 10.112172 | AH5: 7.4944258 | AI5: 23.815197 | AJ5: 0.39833713 | AK5: 28.062012 | AL5: 8.3515224 | AM5: 39.181835 | AN5: 49.305893 | AO5: 5.0999999 | AP5: 16.46701 | AQ5: 4.0648746 | AR5: 27.729189 | AS5: 26.242359 | AT5: 18.904861 | AU5: 8.5540113 | AV5: 15.935916 | AW5: 25.146549 | AX5: 25.695059 | AY5: 13.27812 | AZ5: 1169.4301
A6: 40269 | B6: 7.809104 | C6: 17.251463 | D6: 33.599998 | E6: 4.8400002 | F6: 38.249771 | G6: 6.855 | H6: 46.010052 | I6: 6.3711591 | J6: 41.871731 | K6: 17.266586 | L6: 42.15712 | M6: 31.112057 | N6: 40.626511 | O6: 33.60825 | P6: 38.943703 | Q6: 5.8000002 | R6: 68.43 | S6: 52.515423 | T6: 65.664337 | U6: 13.031651 | V6: 108.25865 | W6: 23.714102 | X6: 13.44 | Y6: 39.847496 | Z6: 28.006279 | AA6: 16.254335 | AB6: 31.751917 | AC6: 45.106598 | AD6: 29.287857 | AE6: 21.10214 | AF6: 22.785816 | AG6: 9.1175337 | AH6: 8.0712748 | AI6: 25.374081 | AJ6: 0.35964802 | AK6: 28.950413 | AL6: 9.0722399 | AM6: 38.790707 | AN6: 52.687397 | AO6: 5.4499998 | AP6: 16.841808 | AQ6: 4.3103895 | AR6: 25.561619 | AS6: 25.291336 | AT6: 21.807068 | AU6: 9.3225031 | AV6: 17.015764 | AW6: 23.351475 | AX6: 26.522348 | AY6: 12.81004 | AZ6: 1186.6899
A7: 40299 | B7: 7.6831861 | C7: 16.037525 | D7: 32.080002 | E7: 6.1799998 | F7: 34.558952 | G7: 6.2729998 | H7: 41.056984 | I7: 5.8297567 | J7: 41.425327 | K7: 14.849387 | L7: 38.595581 | M7: 28.223803 | N7: 39.287296 | O7: 30.084553 | P7: 36.415077 | Q7: 5.1799998 | R7: 70.330002 | S7: 46.697178 | T7: 56.925346 | U7: 12.03835 | V7: 107.82677 | W7: 22.791924 | X7: 12.89 | Y7: 36.459229 | Z7: 26.033079 | AA7: 15.630922 | AB7: 28.591173 | AC7: 43.088554 | AD7: 26.264555 | AE7: 18.930477 | AF7: 19.336174 | AG7: 8.8639984 | AH7: 7.7425361 | AI7: 27.577034 | AJ7: 0.3008132 | AK7: 20.450924 | AL7: 8.210062 | AM7: 38.122982 | AN7: 46.992233 | AO7: 5.0599999 | AP7: 15.675093 | AQ7: 4.0532951 | AR7: 23.625828 | AS7: 28.302912 | AT7: 21.503983 | AU7: 9.1755466 | AV7: 15.975584 | AW7: 22.396147 | AX7: 25.160618 | AY7: 12.144636 | AZ7: 1089.41
A8: 40330 | B8: 7.52317 | C8: 15.774508 | D8: 26.43 | E8: 5.98 | F8: 35.106228 | G8: 5.4629998 | H8: 40.59074 | I8: 5.5977273 | J8: 38.993122 | K8: 13.663237 | L8: 35.455475 | M8: 26.602324 | N8: 37.482468 | O8: 28.303078 | P8: 34.167805 | Q8: 3.47 | R8: 68.57 | S8: 40.560402 | T8: 50.524487 | U8: 11.029929 | V8: 98.117386 | W8: 19.027157 | X8: 11.07 | Y8: 36.934513 | Z8: 24.079611 | AA8: 15.37061 | AB8: 26.516083 | AC8: 42.444191 | AD8: 24.31381 | AE8: 16.207167 | AF8: 17.245173 | AG8: 8.2789145 | AH8: 7.6391497 | AI8: 27.306248 | AJ8: 0.23373687 | AK8: 19.845402 | AL8: 7.9848285 | AM8: 37.430279 | AN8: 42.404636 | AO8: 4.52 | AP8: 14.333068 | AQ8: 4.0532951 | AR8: 21.818672 | AS8: 22.11134 | AT8: 19.416162 | AU8: 8.4670925 | AV8: 15.229796 | AW8: 21.97179 | AX8: 24.48432 | AY8: 11.546535 | AZ8: 1030.71
A9: 40360 | B9: 7.6942554 | C9: 16.703766 | D9: 28.719999 | E9: 5.2800002 | F9: 36.394352 | G9: 5.8944998 | H9: 47.445633 | I9: 6.3082628 | J9: 40.330116 | K9: 14.791686 | L9: 39.818192 | M9: 28.451824 | N9: 40.820908 | O9: 32.092796 | P9: 33.914837 | Q9: 3.1199999 | R9: 87.830002 | S9: 42.42355 | T9: 56.480911 | U9: 12.019013 | V9: 112.73003 | W9: 19.325409 | X9: 13.02 | Y9: 36.327911 | Z9: 26.529722 | AA9: 16.900934 | AB9: 29.10158 | AC9: 44.931435 | AD9: 24.93807 | AE9: 18.881651 | AF9: 19.343664 | AG9: 7.098999 | AH9: 8.1937551 | AI9: 30.958279 | AJ9: 0.21038619 | AK9: 21.869717 | AL9: 8.6736622 | AM9: 38.465351 | AN9: 47.496857 | AO9: 4.52 | AP9: 15.269027 | AQ9: 4.1482577 | AR9: 25.300095 | AS9: 23.963861 | AT9: 19.404938 | AU9: 8.3803034 | AV9: 16.228354 | AW9: 23.557779 | AX9: 26.301882 | AY9: 12.295967 | AZ9: 1101.6
A10: 40391 | B10: 7.2710314 | C10: 16.792261 | D10: 27.700001 | E10: 5.2199998 | F10: 34.065056 | G10: 6.2414999 | H10: 44.323399 | I10: 5.5403862 | J10: 40.326939 | K10: 12.816904 | L10: 39.067268 | M10: 27.480623 | N10: 39.560646 | O10: 30.421406 | P10: 30.217262 | Q10: 2.97 | R10: 87.43 | S10: 38.697205 | T10: 50.734722 | U10: 11.155608 | V10: 102.60497 | W10: 19.018042 | X10: 12.51 | Y10: 35.995041 | Z10: 23.947889 | AA10: 17.137068 | AB10: 30.924129 | AC10: 47.429737 | AD10: 21.214556 | AE10: 17.272614 | AF10: 17.683756 | AG10: 6.2993851 | AH10: 8.4960394 | AI10: 29.553095 | AJ10: 0.21359117 | AK10: 22.103975 | AL10: 7.9988599 | AM10: 37.528255 | AN10: 45.419838 | AO10: 4.3099999 | AP10: 14.553296 | AQ10: 4.1830006 | AR10: 25.573988 | AS10: 21.774519 | AT10: 19.852673 | AU10: 8.0389967 | AV10: 15.130688 | AW10: 24.540329 | AX10: 25.810125 | AY10: 12.11404 | AZ10: 1049.33
A11: 40422 | B11: 8.4868593 | C11: 17.779243 | D11: 26.15 | E11: 3.97 | F11: 36.78146 | G11: 7.8530002 | H11: 53.52002 | I11: 5.857903 | J11: 46.029835 | K11: 14.041528 | L11: 42.743011 | M11: 27.953552 | N11: 42.479538 | O11: 34.340652 | P11: 32.339104 | Q11: 3.9200001 | R11: 103.81 | S11: 43.504051 | T11: 57.357616 | U11: 13.033882 | V11: 108.33727 | W11: 21.656784 | X11: 15.99 | Y11: 39.113522 | Z11: 25.06757 | AA11: 18.082651 | AB11: 36.333977 | AC11: 48.371052 | AD11: 22.651354 | AE11: 17.265621 | AF11: 18.452291 | AG11: 7.0307398 | AH11: 8.6004019 | AI11: 36.440041 | AJ11: 0.26738951 | AK11: 23.805643 | AL11: 8.3959122 | AM11: 37.716927 | AN11: 53.788242 | AO11: 5.29 | AP11: 16.192762 | AQ11: 4.9681816 | AR11: 30.134584 | AS11: 27.14385 | AT11: 21.195366 | AU11: 9.0395679 | AV11: 17.838697 | AW11: 27.263193 | AX11: 28.945286 | AY11: 12.93067 | AZ11: 1141.2
A12: 40452 | B12: 9.0021982 | C12: 17.610949 | D12: 28.15 | E12: 3.04 | F12: 38.169697 | G12: 8.2615004 | H12: 53.760086 | I12: 6.7199244 | J12: 44.94688 | K12: 14.657049 | L12: 43.560436 | M12: 30.512447 | N12: 41.290722 | O12: 35.801399 | P12: 33.347939 | Q12: 4.4699998 | R12: 117.7 | S12: 47.496525 | T12: 56.545784 | U12: 15.213097 | V12: 120.73859 | W12: 21.123566 | X12: 16.66 | Y12: 40.237183 | Z12: 24.816315 | AA12: 18.947847 | AB12: 48.353035 | AC12: 50.487423 | AD12: 23.923225 | AE12: 17.434574 | AF12: 20.094835 | AG12: 8.0546322 | AH12: 8.703186 | AI12: 38.972305 | AJ12: 0.2751731 | AK12: 27.345989 | AL12: 9.3768234 | AM12: 40.288433 | AN12: 58.770924 | AO12: 6.29 | AP12: 17.429321 | AQ12: 4.870903 | AR12: 30.154615 | AS12: 25.86591 | AT12: 20.583258 | AU12: 9.2947741 | AV12: 19.5221 | AW12: 27.993095 | AX12: 31.025949 | AY12: 13.087716 | AZ12: 1183.26
A13: 40483 | B13: 9.3063831 | C13: 15.960345 | D13: 27.799999 | E13: 4.1500001 | F13: 35.166294 | G13: 8.7700005 | H13: 57.863949 | I13: 6.5277438 | J13: 48.412598 | K13: 12.28473 | L13: 43.066219 | M13: 30.833363 | N13: 40.026562 | O13: 36.131485 | P13: 30.989317 | Q13: 5.79 | R13: 131.88 | S13: 46.081093 | T13: 55.875141 | U13: 13.775572 | V13: 117.25708 | W13: 20.811911 | X13: 14.51 | Y13: 39.189053 | Z13: 24.664631 | AA13: 19.654392 | AB13: 49.585007 | AC13: 51.22937 | AD13: 22.768824 | AE13: 17.147156 | AF13: 19.149395 | AG13: 7.0892472 | AH13: 8.0818462 | AI13: 37.274361 | AJ13: 0.31157291 | AK13: 30.541578 | AL13: 9.6196251 | AM13: 38.704029 | AN13: 61.815731 | AO13: 6.3899999 | AP13: 18.047602 | AQ13: 5.3735108 | AR13: 31.387386 | AS13: 28.550577 | AT13: 21.024641 | AU13: 9.267581 | AV13: 20.994349 | AW13: 28.358059 | AX13: 32.019882 | AY13: 13.06838 | AZ13: 1180.55
A14: 40513 | B14: 9.6476536 | C14: 16.440769 | D14: 30.780001 | E14: 4.0999999 | F14: 36.641296 | G14: 9 | H14: 64.060722 | I14: 7.1564093 | J14: 51.706451 | K14: 12.970778 | L14: 48.533924 | M14: 32.024368 | N14: 42.3606 | O14: 37.509304 | P14: 31.846365 | Q14: 8.21 | R14: 130.16 | S14: 49.476677 | T14: 65.067108 | U14: 14.724005 | V14: 126.28389 | W14: 24.153122 | X14: 16.559999 | Y14: 39.38007 | Z14: 27.975245 | AA14: 20.463346 | AB14: 49.912537 | AC14: 50.221771 | AD14: 25.186277 | AE14: 19.074982 | AF14: 21.158337 | AG14: 7.8206005 | AH14: 8.3005781 | AI14: 40.223812 | AJ14: 0.35255128 | AK14: 32.543793 | AL14: 10.440233 | AM14: 40.770103 | AN14: 66.492508 | AO14: 5.9099998 | AP14: 19.78241 | AQ14: 5.4754219 | AR14: 33.177319 | AS14: 32.523087 | AT14: 23.740242 | AU14: 9.0196905 | AV14: 21.45648 | AW14: 28.132109 | AX14: 32.926014 | AY14: 13.101785 | AZ14: 1257.64
... A203: 46266 | B203: 315.34 | C203: 105.23 | D203: 254.86 | E203: 119.23 | F203: 391.26999 | G203: 252.39999 | H203: 815.56 | I203: 24.59 | J203: 902.59998 | K203: 109.43 | L203: 213.81 | M203: 104.18 | N203: 272.20999 | O203: 150.34 | P203: 147.00999 | Q203: 58.330002 | R203: 404.63 | S203: 352.67001 | T203: 325.42001 | U203: 330.64999 | V203: 1028.78 | W203: 310.45001 | X203: 126.01 | Y203: 267.07999 | Z203: 354.70999 | AA203: 87.550003 | AB203: 120.87 | AC203: 253.48 | AD203: 91.889999 | AE203: 215.35001 | AF203: 491.64999 | AG203: 1027.77 | AH203: 82.650002 | AI203: 184.74001 | AJ203: 223.67 | AK203: 48.490002 | AL203: 95.82 | AM203: 142.64 | AN203: 949.46997 | AO203: 29.1 | AP203: 135.66 | AQ203: 88.290001 | AR203: 176.39999 | AS203: 807.65002 | AT203: 320.64001 | AU203: 126.12 | AV203: 261.59 | AW203: 393.06 | AX203: 284.73999 | AY203: 105.83 | AZ203: 7636.3599

Sheet Returns
A1: Returns
A2: Date | B2: AAPL | C2: ABT | D2: ADBE | E2: ADUS | F2: AMGN | G2: AMZN | H2: CAT | I2: CMCSA | J2: COST | K2: CSCO | L2: CVX | M2: DIS | N2: ECL | O2: EMR | P2: EOG | Q2: EXEL | R2: FFIV | S2: GD | T2: GE | U2: GOOGL | V2: GS | W2: HD | X2: INCY | Y2: JNJ | Z2: JPM | AA2: KO | AB2: LNN | AC2: MCD | AD2: MDT | AE2: MS | AF2: MSFT | AG2: MU | AH2: NEE | AI2: NTAP | AJ2: NVDA | AK2: OII | AL2: OKE | AM2: PG | AN2: PH | AO2: PLAB | AP2: PLD | AQ2: PLUS | AR2: QCOM | AS2: REGN | AT2: SHW | AU2: TJX | AV2: TXN | AW2: UNH | AX2: UNP | AY2: WMT | AZ2: ^GSPC
A3: 40210 | B3: 0.065396013 | C3: 0.025311914 | D3: 0.072755491 | E3: -0.10430835 | F3: -0.031976746 | G3: -0.055896674 | H3: 0.092074474 | I3: 0.038534645 | J3: 0.064902503 | K3: 0.082776841 | L3: 0.012090985 | M3: 0.057191314 | N3: -0.040091314 | O3: 0.14801925 | P3: 0.040146209 | Q3: -0.024132779 | R3: 0.12886909 | S3: 0.085265552 | T3: 0.0049904821 | U3: -0.0059250581 | V3: 0.053661809 | W3: 0.11388792 | X3: -0.001872702 | Y3: 0.0098952973 | Z3: 0.077812355 | AA3: -0.028203211 | AB3: -0.083317926 | AC3: 0.0314384 | AD3: 0.01189063 | AE3: 0.052277476 | AF3: 0.022145557 | AG3: 0.038990732 | AH3: -0.038745299 | AI3: 0.030209285 | AJ3: 0.052631637 | AK3: 0.10511889 | AL3: 0.050723124 | AM3: 0.028107526 | AN3: 0.083528247 | AO3: 0.1428572 | AP3: 0.014166235 | AQ3: 0.043256888 | AR3: -0.059900424 | AS3: -0.08252079 | AT3: 0.0061212562 | AU3: 0.098727312 | AV3: 0.083555606 | AW3: 0.026060566 | AX3: 0.118101 | AY3: 0.011977995 | AZ3: 0.028513689
A4: 40238 | B4: 0.1484706 | C4: -0.029476781 | D4: 0.020779145 | E4: -0.23544305 | F4: 0.057056913 | G4: 0.14670604 | H4: 0.10166529 | I4: 0.14537718 | J4: -0.020665693 | K4: 0.069873378 | L4: 0.04882408 | M4: 0.11747739 | N4: 0.046753726 | O4: 0.063372167 | P4: -0.011802593 | Q4: -0.061823745 | R4: 0.10448032 | S4: 0.064094192 | T4: 0.13325103 | U4: 0.076537531 | V4: 0.091333319 | W4: 0.044571908 | X4: 0.30675427 | Y4: 0.034920692 | Z4: 0.066237255 | AA4: 0.051785732 | AB4: 0.12496611 | AC4: 0.044948777 | AD4: 0.037558086 | AE4: 0.039390022 | AF4: 0.021625721 | AG4: 0.14459173 | AH4: 0.042268336 | AI4: 0.084305706 | AJ4: 0.074073863 | AK4: 0.050289268 | AL4: 0.029776867 | AM4: -0.00015828039 | AN4: 0.073453656 | AO4: 0.15909086 | AP4: 0.13054455 | AQ4: 0.070121689 | AR4: 0.14394795 | AS4: 0.082992809 | AT4: 0.067844878 | AU4: 0.02137856 | AV4: 0.0036914902 | AW4: -0.035144889 | AX4: 0.088021476 | AY4: 0.034092377 | AZ4: 0.058796426
A5: 40269 | B5: 0.1110209 | C5: -0.020672801 | D5: -0.050042423 | E5: -0.19867547 | F5: -0.04227956 | G5: 0.0097960063 | H5: 0.090131445 | I5: 0.055235457 | J5: -0.010551339 | K5: 0.034574919 | L5: 0.073981467 | M5: 0.055285378 | N5: 0.11126211 | O5: 0.037543986 | P5: 0.2081137 | Q5: -0.04448105 | R5: 0.11033586 | S5: -0.0054850522 | T5: 0.036263259 | U5: -0.073035668 | V5: -0.14903556 | W5: 0.089026773 | X5: -0.035175931 | Y5: -0.013803638 | Z5: -0.04742697 | AA5: -0.028181634 | AB5: -0.081623048 | AC5: 0.058003707 | AD5: -0.025361294 | AE5: 0.033477998 | AF5: 0.042676552 | AG5: -0.098360514 | AH5: 0.076970405 | AI5: 0.065457517 | AJ5: -0.09712654 | AK5: 0.031658494 | AL5: 0.08629773 | AM5: -0.0099823946 | AN5: 0.068582148 | AO5: 0.068627434 | AP5: 0.022760526 | AQ5: 0.060399124 | AR5: -0.078169258 | AS5: -0.03624 | AT5: 0.15351641 | AU5: 0.089839926 | AV5: 0.067761922 | AW5: -0.071384525 | AX5: 0.032196446 | AY5: -0.035252018 | AZ5: 0.01475923
A6: 40299 | B6: -0.016124502 | C6: -0.070367236 | D6: -0.045237997 | E6: 0.27685943 | F6: -0.096492572 | G6: -0.084901569 | H6: -0.10765186 | I6: -0.084977056 | J6: -0.010661214 | K6: -0.13999288 | L6: -0.084482496 | M6: -0.092833919 | N6: -0.03296405 | O6: -0.10484619 | P6: -0.064930279 | Q6: -0.10689661 | R6: 0.027765622 | S6: -0.11079117 | T6: -0.1330858 | U6: -0.076222151 | V6: -0.0039893083 | W6: -0.038887337 | X6: -0.040922564 | Y6: -0.085030877 | Z6: -0.070455623 | AA6: -0.03835365 | AB6: -0.099544973 | AC6: -0.044739431 | AD6: -0.10322715 | AE6: -0.10291199 | AF6: -0.15139428 | AG6: -0.02780744 | AH6: -0.040729463 | AI6: 0.086819041 | AJ6: -0.16359 | AK6: -0.29358783 | AL6: -0.095034728 | AM6: -0.01721352 | AN6: -0.10809347 | AO6: -0.071559611 | AP6: -0.069274961 | AQ6: -0.059645278 | AR6: -0.075730376 | AS6: 0.11907539 | AT6: -0.013898491 | AU6: -0.015763625 | AV6: -0.061130384 | AW6: -0.04091082 | AX6: -0.05134276 | AY6: -0.051943896 | AZ6: -0.081975842
A7: 40330 | B7: -0.020826784 | C7: -0.01640014 | D7: -0.17612223 | E7: -0.03236243 | F7: 0.015835999 | G7: -0.12912482 | H7: -0.011356015 | I7: -0.039800878 | J7: -0.058712999 | K7: -0.079878754 | L7: -0.081359216 | M7: -0.057450764 | N7: -0.045939243 | O7: -0.059215607 | P7: -0.061712693 | Q7: -0.3301158 | R7: -0.025024912 | S7: -0.13141642 | T7: -0.11244305 | U7: -0.083767371 | V7: -0.090046176 | W7: -0.16517986 | X7: -0.14119477 | Y7: 0.013036057 | Z7: -0.075037928 | AA7: -0.016653661 | AB7: -0.072578008 | AC7: -0.014954398 | AD7: -0.074272899 | AE7: -0.14385852 | AF7: -0.10813936 | AG7: -0.066006776 | AH7: -0.013353041 | AI7: -0.0098192679 | AJ7: -0.22298332 | AK7: -0.029608548 | AL7: -0.027433843 | AM7: -0.018170227 | AN7: -0.097624577 | AO7: -0.10671936 | AP7: -0.085615111 | AQ7: 0 | AR7: -0.076490679 | AS7: -0.21876096 | AT7: -0.097089925 | AU7: -0.077211109 | AV7: -0.046682964 | AW7: -0.018947744 | AX7: -0.026879234 | AY7: -0.049248212 | AZ7: -0.053882442
A8: 40360 | B8: 0.022741126 | C8: 0.058908866 | D8: 0.086643927 | E8: -0.11705682 | F8: 0.036692181 | G8: 0.0789859 | H8: 0.16887824 | I8: 0.12693286 | J8: 0.034287949 | K8: 0.0825902 | L8: 0.12304776 | M8: 0.069524027 | N8: 0.089066706 | O8: 0.13389776 | P8: -0.00740369 | Q8: -0.10086459 | R8: 0.28088088 | S8: 0.04593514 | T8: 0.11789184 | U8: 0.089672765 | V8: 0.14893026 | W8: 0.015675075 | X8: 0.17615184 | Y8: -0.01642371 | Z8: 0.10175046 | AA8: 0.099561693 | AB8: 0.097506744 | AC8: 0.058600331 | AD8: 0.025675118 | AE8: 0.16501862 | AF8: 0.12168575 | AG8: -0.14252055 | AH8: 0.072600421 | AI8: 0.13374342 | AJ8: -0.099901593 | AK8: 0.10200423 | AL8: 0.086267816 | AM8: 0.027653343 | AN8: 0.1200864 | AO8: 0 | AP8: 0.065300665 | AQ8: 0.023428493 | AR8: 0.15956161 | AS8: 0.083781532 | AT8: -0.00057811355 | AU8: -0.010250169 | AV8: 0.065566017 | AW8: 0.072182966 | AX8: 0.074233719 | AY8: 0.06490541 | AZ8: 0.06877785
A9: 40391 | B9: -0.055005189 | C9: 0.0052979223 | D9: -0.035515271 | E9: -0.011363715 | F9: -0.064001582 | G9: 0.05886846 | H9: -0.06580657 | I9: -0.12172553 | J9: -7.8790817e-05 | K9: -0.13350621 | L9: -0.018858796 | M9: -0.034134927 | N9: -0.030872943 | O9: -0.052079928 | P9: -0.10902528 | Q9: -0.048076879 | R9: -0.0045542698 | S9: -0.087836711 | T9: -0.10173683 | U9: -0.071836614 | V9: -0.08981689 | W9: -0.015904829 | X9: -0.039170523 | Y9: -0.0091629403 | Z9: -0.097318504 | AA9: 0.013971629 | AB9: 0.062627178 | AC9: 0.055602553 | AD9: -0.14931045 | AE9: -0.085216987 | AF9: -0.085811472 | AG9: -0.11263756 | AH9: 0.036892028 | AI9: -0.045389597 | AJ9: 0.015233825 | AK9: 0.010711554 | AL9: -0.077799007 | AM9: -0.024362072 | AN9: -0.043729604 | AO9: -0.046460186 | AP9: -0.046874675 | AQ9: 0.0083752829 | AR9: 0.010825784 | AS9: -0.091360172 | AT9: 0.023073242 | AU9: -0.040727247 | AV9: -0.067638765 | AW9: 0.041708077 | AX9: -0.018696626 | AY9: -0.014795642 | AZ9: -0.047449184
A10: 40422 | B10: 0.16721533 | C10: 0.058776024 | D10: -0.055956718 | E10: -0.23946357 | F10: 0.079741656 | G10: 0.25819119 | H10: 0.20748907 | I10: 0.057309507 | J10: 0.14141654 | K10: 0.095547542 | L10: 0.094087538 | M10: 0.017209544 | N10: 0.073782716 | O10: 0.12883187 | P10: 0.070219513 | Q10: 0.31986533 | R10: 0.18734985 | S10: 0.1242169 | T10: 0.13053968 | U10: 0.16837038 | V10: 0.055867661 | W10: 0.13874943 | X10: 0.27817742 | Y10: 0.086636398 | Z10: 0.046754868 | AA10: 0.055177663 | AB10: 0.17493935 | AC10: 0.019846509 | AD10: 0.067726994 | AE10: -0.00040482236 | AF10: 0.043459976 | AG10: 0.11609938 | AH10: 0.012283663 | AI10: 0.23303636 | AJ10: 0.25187526 | AK10: 0.076984695 | AL10: 0.04963861 | AM10: 0.0050274416 | AN10: 0.18424558 | AO10: 0.2273782 | AP10: 0.11265258 | AQ10: 0.18770761 | AR10: 0.1783295 | AS10: 0.24658783 | AT10: 0.067632875 | AU10: 0.12446469 | AV10: 0.17897466 | AW10: 0.11095467 | AX10: 0.12147018 | AY10: 0.067411812 | AZ10: 0.087551103
A11: 40452 | B11: 0.060721979 | C11: -0.0094658081 | D11: 0.076481837 | E11: -0.23425694 | F11: 0.037742847 | G11: 0.052018361 | H11: 0.0044855464 | I11: 0.1471553 | J11: -0.023527228 | K11: 0.043835788 | L11: 0.019124174 | M11: 0.091540964 | N11: -0.027985617 | O11: 0.042536954 | P11: 0.03119551 | Q11: 0.14030605 | R11: 0.13380214 | S11: 0.091772455 | T11: -0.014153873 | U11: 0.16719612 | V11: 0.1144695 | W11: -0.02462131 | X11: 0.041901194 | Y11: 0.028728199 | Z11: -0.010023111 | AA11: 0.047846758 | AB11: 0.33079391 | AC11: 0.043752845 | AD11: 0.056149914 | AE11: 0.0097855119 | AF11: 0.089015708 | AG11: 0.14563082 | AH11: 0.011951088 | AI11: 0.06949127 | AJ11: 0.029109563 | AK11: 0.14871878 | AL11: 0.11683201 | AM11: 0.06817911 | AN11: 0.092635138 | AO11: 0.18903592 | AP11: 0.076364914 | AQ11: -0.019580322 | AR11: 0.00066471716 | AS11: -0.047080305 | AT11: -0.028879342 | AU11: 0.028232113 | AV11: 0.094368046 | AW11: 0.026772442 | AX11: 0.071882644 | AY11: 0.012145258 | AZ11: 0.036855994
A12: 40483 | B12: 0.033790071 | C12: -0.093725973 | D12: -0.012433406 | E12: 0.36513163 | F12: -0.078685527 | G12: 0.061550575 | H12: 0.076336611 | I12: -0.02859863 | J12: 0.07710696 | K12: -0.16185517 | L12: -0.011345546 | M12: 0.010517518 | N12: -0.030616083 | O12: 0.0092199121 | P12: -0.070727658 | Q12: 0.29530207 | R12: 0.12047586 | S12: -0.029800748 | T12: -0.011860174 | U12: -0.094492583 | V12: -0.028835076 | W12: -0.014753903 | X12: -0.1290516 | Y12: -0.026048793 | Z12: -0.0061122616 | AA12: 0.037288926 | AB12: 0.025478685 | AC12: 0.014695683 | AD12: -0.048254437 | AE12: -0.01648554 | AF12: -0.04704892 | AG12: -0.11985463 | AH12: -0.071392223 | AI12: -0.043567981 | AJ12: 0.13227969 | AK12: 0.11685769 | AL12: 0.025893808 | AM12: -0.039326523 | AN12: 0.051808058 | AO12: 0.015898236 | AP12: 0.035473579 | AQ12: 0.10318576 | AR12: 0.040881666 | AS12: 0.10379173 | AT12: 0.021443805 | AU12: -0.00292563 | AV12: 0.07541443 | AW12: 0.013037627 | AX12: 0.03203553 | AY12: -0.0014773966 | AZ12: -0.0022902497
A13: 40513 | B13: 0.036670578 | C13: 0.030101099 | D13: 0.1071943 | E13: -0.012048238 | F13: 0.041943637 | G13: 0.026225716 | H13: 0.10709213 | I13: 0.096306697 | J13: 0.068037121 | K13: 0.055845554 | L13: 0.12696041 | M13: 0.038627175 | N13: 0.058312223 | O13: 0.038133474 | P13: 0.027656242 | Q13: 0.41796202 | R13: -0.013042168 | S13: 0.073687144 | T13: 0.16450906 | U13: 0.068848897 | V13: 0.076983067 | W13: 0.16054323 | X13: 0.14128182 | Y13: 0.0048742477 | Z13: 0.13422514 | AA13: 0.041158955 | AB13: 0.0066054223 | AC13: -0.019668383 | AD13: 0.10617385 | AE13: 0.11242832 | AF13: 0.10490888 | AG13: 0.10316374 | AH13: 0.027064593 | AI13: 0.079128157 | AJ13: 0.13152097 | AK13: 0.065557006 | AL13: 0.085305626 | AM13: 0.053381377 | AN13: 0.075656743 | AO13: -0.075117375 | AP13: 0.096124017 | AQ13: 0.018965453 | AR13: 0.05702712 | AS13: 0.13913937 | AT13: 0.12916277 | AU13: -0.026748131 | AV13: 0.022012186 | AW13: -0.0079677612 | AX13: 0.028299034 | AY13: 0.0025561201 | AZ13: 0.06530004
A14: 40544 | B14: 0.051958434 | C14: -0.048649558 | D14: 0.073749139 | E14: 0.12926835 | F14: 0.0032785039 | G14: -0.057555517 | H14: 0.040638156 | I14: 0.040000392 | J14: -0.0051239674 | K14: 0.04547673 | L14: 0.040328693 | M14: 0.036257075 | N14: -0.014478264 | O14: 0.029910792 | P14: 0.16574488 | Q14: 0.056029237 | R14: -0.16733256 | S14: 0.068871321 | T14: 0.1011489 | U14: 0.010758109 | V14: -0.026998694 | W14: 0.04877309 | X14: -0.10990337 | Y14: -0.033629723 | Z14: 0.060622271 | AA14: -0.044397231 | AB14: 0.095069485 | AC14: -0.040255106 | AD14: 0.039466748 | AE14: 0.082350444 | AF14: -0.0064494366 | AG14: 0.31421436 | AH14: 0.028274704 | AI14: -0.0041847682 | AJ14: 0.55324643 | AK14: 0.048893585 | AL14: 0.071074188 | AM14: -0.011379034 | AN14: 0.036037289 | AO14: 0.11505928 | AP14: 0.058025894 | AQ14: 0.093062732 | AR14: 0.093756004 | AS14: 0.025891032 | AT14: 0.011701633 | AU14: 0.067582832 | AV14: 0.047352142 | AW14: 0.13680407 | AX14: 0.021260504 | AY14: 0.039681205 | AZ14: 0.022645574
... A202: 46266 | B202: -0.0047656927 | C202: -0.046484208 | D202: -0.1295468 | E202: 0.039766332 | F202: -0.089815798 | G202: -0.028371234 | H202: 0.022684273 | I202: -0.076258476 | J202: -0.043744545 | K202: -0.0095936065 | L202: 0.037207714 | M202: -0.031334288 | N202: -0.038806569 | O202: -0.013775952 | P202: 0.014141747 | Q202: 0.067532988 | R202: -0.0061405447 | S202: -0.050302928 | T202: -0.03065139 | U202: -0.025010983 | V202: 0.0077186842 | W202: -0.046036624 | X202: 0.022642435 | Y202: 0.0046265956 | Z202: -0.0036795618 | AA202: -0.012631049 | AB202: 0.051866669 | AC202: -0.031336085 | AD202: 0.013678961 | AE202: 0.0095162137 | AF202: -0.03083052 | AG202: 0.072011975 | AH202: 0.0037649405 | AI202: -0.0029682542 | AJ202: 0.013089951 | AK202: -0.063176135 | AL202: -0.0019789859 | AM202: -0.017089277 | AN202: -0.03059915 | AO202: 0.034115175 | AP202: -0.03044593 | AQ202: 0.0036376002 | AR202: 0.040357002 | AS202: 0.010724842 | AT202: -0.053628827 | AU202: -0.058173405 | AV202: 0.0026062346 | AW202: 0.0093731385 | AX202: -0.052981749 | AY202: 0.0091541819 | AZ202: -0.0064766284

Sheet Data Notes
A1: Data Build Notes
A2: Generated: 2026-09-10 14:10
A4: Final sample period: | B4: 2010-01-01 to 2026-09-01
A5: Final ticker count (excl. market): | B5: 50
A6: Months dropped in complete-case alignment: | B6: 0
A8: Tickers dropped — no data returned at all:
A9: (none)
A11: Tickers dropped — >5% missing monthly observations:
A12: (none)
A14: Extreme monthly returns flagged (< -50% or > +200%, NOT removed):
A15: Date | B15: Ticker | C15: Return
A16: 2014-09-01 | B16: EXEL | C16: -63.04%
A17: 2020-03-01 | B17: OII | C17: -72.11%
A18: 2020-03-01 | B18: OKE | C18: -67.31%
